multiprocessing.pool.RemoteTraceback: 
"""
Traceback (most recent call last):
  File "/g/data3/hh5/public/apps/miniconda3/envs/analysis3-20.10/lib/python3.8/multiprocessing/pool.py", line 125, in worker
    result = (True, func(*args, **kwds))
  File "/g/data3/hh5/public/apps/miniconda3/envs/analysis3-20.10/lib/python3.8/multiprocessing/pool.py", line 51, in starmapstar
    return list(itertools.starmap(args[0], args[1]))
  File "/g/data3/w48/dm5220/scripts/um2nc/convert_um2nc.py", line 41, in convert
    iris.save(x,os.path.join(output_folder,'{}_p{}{}.nc'.format(exp_id,s,Constants.um.from_um_filename_years(year))))
  File "/g/data3/hh5/public/apps/miniconda3/envs/analysis3-20.10/lib/python3.8/site-packages/iris/io/__init__.py", line 431, in save
    saver(source, target, **kwargs)
  File "/g/data3/hh5/public/apps/miniconda3/envs/analysis3-20.10/lib/python3.8/site-packages/iris/fileformats/netcdf.py", line 2321, in save
    attributes = cubes[0].attributes
  File "/g/data3/hh5/public/apps/miniconda3/envs/analysis3-20.10/lib/python3.8/site-packages/iris/cube.py", line 245, in __getitem__
    result = super(CubeList, self).__getitem__(keys)
IndexError: list index out of range
"""

The above exception was the direct cause of the following exception:

Traceback (most recent call last):
  File "/g/data3/w48/dm5220/scripts/um2nc/convert_um2nc.py", line 50, in <module>
    main(input_folder,output_folder,exp_id,years)
  File "/g/data3/w48/dm5220/scripts/um2nc/convert_um2nc.py", line 45, in main
    p.starmap(convert,zip(repeat(input_folder),repeat(exp_id),years,repeat(output_folder)))
  File "/g/data3/hh5/public/apps/miniconda3/envs/analysis3-20.10/lib/python3.8/multiprocessing/pool.py", line 372, in starmap
    return self._map_async(func, iterable, starmapstar, chunksize).get()
  File "/g/data3/hh5/public/apps/miniconda3/envs/analysis3-20.10/lib/python3.8/multiprocessing/pool.py", line 771, in get
    raise self._value
  File "/g/data3/hh5/public/apps/miniconda3/envs/analysis3-20.10/lib/python3.8/multiprocessing/pool.py", line 125, in worker
    result = (True, func(*args, **kwds))
  File "/g/data3/hh5/public/apps/miniconda3/envs/analysis3-20.10/lib/python3.8/multiprocessing/pool.py", line 51, in starmapstar
    return list(itertools.starmap(args[0], args[1]))
  File "/g/data3/w48/dm5220/scripts/um2nc/convert_um2nc.py", line 41, in convert
    iris.save(x,os.path.join(output_folder,'{}_p{}{}.nc'.format(exp_id,s,Constants.um.from_um_filename_years(year))))
  File "/g/data3/hh5/public/apps/miniconda3/envs/analysis3-20.10/lib/python3.8/site-packages/iris/io/__init__.py", line 431, in save
    saver(source, target, **kwargs)
  File "/g/data3/hh5/public/apps/miniconda3/envs/analysis3-20.10/lib/python3.8/site-packages/iris/fileformats/netcdf.py", line 2321, in save
    attributes = cubes[0].attributes
  File "/g/data3/hh5/public/apps/miniconda3/envs/analysis3-20.10/lib/python3.8/site-packages/iris/cube.py", line 245, in __getitem__
    result = super(CubeList, self).__getitem__(keys)
IndexError: list index out of range
