multiprocessing.pool.RemoteTraceback: 
"""
Traceback (most recent call last):
  File "/g/data3/hh5/public/apps/miniconda3/envs/analysis3-21.04/lib/python3.8/multiprocessing/pool.py", line 125, in worker
    result = (True, func(*args, **kwds))
  File "/g/data3/hh5/public/apps/miniconda3/envs/analysis3-21.04/lib/python3.8/multiprocessing/pool.py", line 51, in starmapstar
    return list(itertools.starmap(args[0], args[1]))
  File "/g/data3/w48/dm5220/scripts/um2nc/convert_um2nc.py", line 41, in convert
    x=iris.load(os.path.join(input_folder,exp_id,"{}a@p{}{}*".format(exp_id,s,year)))
  File "/g/data3/hh5/public/apps/miniconda3/envs/analysis3-21.04/lib/python3.8/site-packages/iris/__init__.py", line 357, in load
    return _load_collection(uris, constraints, callback).merged().cubes()
  File "/g/data3/hh5/public/apps/miniconda3/envs/analysis3-21.04/lib/python3.8/site-packages/iris/__init__.py", line 325, in _load_collection
    result = iris.cube._CubeFilterCollection.from_cubes(cubes, constraints)
  File "/g/data3/hh5/public/apps/miniconda3/envs/analysis3-21.04/lib/python3.8/site-packages/iris/cube.py", line 157, in from_cubes
    for cube in cubes:
  File "/g/data3/hh5/public/apps/miniconda3/envs/analysis3-21.04/lib/python3.8/site-packages/iris/__init__.py", line 312, in _generate_cubes
    for cube in iris.io.load_files(part_names, callback, constraints):
  File "/g/data3/hh5/public/apps/miniconda3/envs/analysis3-21.04/lib/python3.8/site-packages/iris/io/__init__.py", line 206, in load_files
    for cube in handling_format_spec.handler(fnames, callback,
  File "/g/data3/hh5/public/apps/miniconda3/envs/analysis3-21.04/lib/python3.8/site-packages/iris/fileformats/rules.py", line 426, in load_cubes
    for cube, field in _load_pairs_from_fields_and_filenames(
  File "/g/data3/hh5/public/apps/miniconda3/envs/analysis3-21.04/lib/python3.8/site-packages/iris/fileformats/rules.py", line 350, in _load_pairs_from_fields_and_filenames
    cube, factories, references = _make_cube(field, converter)
  File "/g/data3/hh5/public/apps/miniconda3/envs/analysis3-21.04/lib/python3.8/site-packages/iris/fileformats/rules.py", line 293, in _make_cube
    metadata = converter(field)
  File "/g/data3/hh5/public/apps/miniconda3/envs/analysis3-21.04/lib/python3.8/site-packages/iris/fileformats/pp_load_rules.py", line 734, in convert
    t1=f.t1, t2=f.t2, lbft=f.lbft)
  File "/g/data3/hh5/public/apps/miniconda3/envs/analysis3-21.04/lib/python3.8/site-packages/iris/fileformats/pp.py", line 1461, in t1
    self._t1 = cftime.datetime(self.lbyr, self.lbmon, self.lbdat,
  File "src/cftime/_cftime.pyx", line 893, in cftime._cftime.datetime.__init__
  File "src/cftime/_cftime.pyx", line 1347, in cftime._cftime.assert_valid_date
ValueError: invalid day number provided in cftime.datetime(2034, 2, 29, 0, 0, 0, 0, calendar='gregorian')
"""

The above exception was the direct cause of the following exception:

Traceback (most recent call last):
  File "/g/data3/w48/dm5220/scripts/um2nc/convert_um2nc.py", line 54, in <module>
    main(input_folder,output_folder,exp_id,years)
  File "/g/data3/w48/dm5220/scripts/um2nc/convert_um2nc.py", line 49, in main
    p.starmap(convert,zip(repeat(input_folder),repeat(output_folder),repeat(exp_id),years))
  File "/g/data3/hh5/public/apps/miniconda3/envs/analysis3-21.04/lib/python3.8/multiprocessing/pool.py", line 372, in starmap
    return self._map_async(func, iterable, starmapstar, chunksize).get()
  File "/g/data3/hh5/public/apps/miniconda3/envs/analysis3-21.04/lib/python3.8/multiprocessing/pool.py", line 771, in get
    raise self._value
  File "/g/data3/hh5/public/apps/miniconda3/envs/analysis3-21.04/lib/python3.8/multiprocessing/pool.py", line 125, in worker
    result = (True, func(*args, **kwds))
  File "/g/data3/hh5/public/apps/miniconda3/envs/analysis3-21.04/lib/python3.8/multiprocessing/pool.py", line 51, in starmapstar
    return list(itertools.starmap(args[0], args[1]))
  File "/g/data3/w48/dm5220/scripts/um2nc/convert_um2nc.py", line 41, in convert
    x=iris.load(os.path.join(input_folder,exp_id,"{}a@p{}{}*".format(exp_id,s,year)))  
  File "/g/data3/hh5/public/apps/miniconda3/envs/analysis3-21.04/lib/python3.8/site-packages/iris/__init__.py", line 357, in load
    return _load_collection(uris, constraints, callback).merged().cubes()
  File "/g/data3/hh5/public/apps/miniconda3/envs/analysis3-21.04/lib/python3.8/site-packages/iris/__init__.py", line 325, in _load_collection
    result = iris.cube._CubeFilterCollection.from_cubes(cubes, constraints)
  File "/g/data3/hh5/public/apps/miniconda3/envs/analysis3-21.04/lib/python3.8/site-packages/iris/cube.py", line 157, in from_cubes
    for cube in cubes:
  File "/g/data3/hh5/public/apps/miniconda3/envs/analysis3-21.04/lib/python3.8/site-packages/iris/__init__.py", line 312, in _generate_cubes
    for cube in iris.io.load_files(part_names, callback, constraints):
  File "/g/data3/hh5/public/apps/miniconda3/envs/analysis3-21.04/lib/python3.8/site-packages/iris/io/__init__.py", line 206, in load_files
    for cube in handling_format_spec.handler(fnames, callback,
  File "/g/data3/hh5/public/apps/miniconda3/envs/analysis3-21.04/lib/python3.8/site-packages/iris/fileformats/rules.py", line 426, in load_cubes
    for cube, field in _load_pairs_from_fields_and_filenames(
  File "/g/data3/hh5/public/apps/miniconda3/envs/analysis3-21.04/lib/python3.8/site-packages/iris/fileformats/rules.py", line 350, in _load_pairs_from_fields_and_filenames
    cube, factories, references = _make_cube(field, converter)
  File "/g/data3/hh5/public/apps/miniconda3/envs/analysis3-21.04/lib/python3.8/site-packages/iris/fileformats/rules.py", line 293, in _make_cube
    metadata = converter(field)
  File "/g/data3/hh5/public/apps/miniconda3/envs/analysis3-21.04/lib/python3.8/site-packages/iris/fileformats/pp_load_rules.py", line 734, in convert
    t1=f.t1, t2=f.t2, lbft=f.lbft)
  File "/g/data3/hh5/public/apps/miniconda3/envs/analysis3-21.04/lib/python3.8/site-packages/iris/fileformats/pp.py", line 1461, in t1
    self._t1 = cftime.datetime(self.lbyr, self.lbmon, self.lbdat,
  File "src/cftime/_cftime.pyx", line 893, in cftime._cftime.datetime.__init__
  File "src/cftime/_cftime.pyx", line 1347, in cftime._cftime.assert_valid_date
ValueError: invalid day number provided in cftime.datetime(2034, 2, 29, 0, 0, 0, 0, calendar='gregorian')
