Traceback (most recent call last):
  File "/g/data3/hh5/public/apps/miniconda3/envs/analysis3-20.10/lib/python3.8/site-packages/xarray/backends/file_manager.py", line 199, in _acquire_with_cache_info
    file = self._cache[self._key]
  File "/g/data3/hh5/public/apps/miniconda3/envs/analysis3-20.10/lib/python3.8/site-packages/xarray/backends/lru_cache.py", line 53, in __getitem__
    value = self._cache[key]
KeyError: [<class 'netCDF4._netCDF4.Dataset'>, ('/g/data/w48/dm5220/data/exp_precip_change/ancil/tac_0.1.nc',), 'a', (('clobber', True), ('diskless', False), ('format', 'NETCDF4'), ('persist', False))]

During handling of the above exception, another exception occurred:

Traceback (most recent call last):
  File "/g/data3/w48/dm5220/scripts/tair_change/mlevel_tair_correction.py", line 43, in <module>
    tac.to_netcdf(output_file,encoding=encoding)
  File "/g/data3/hh5/public/apps/miniconda3/envs/analysis3-20.10/lib/python3.8/site-packages/xarray/core/dataarray.py", line 2664, in to_netcdf
    return dataset.to_netcdf(*args, **kwargs)
  File "/g/data3/hh5/public/apps/miniconda3/envs/analysis3-20.10/lib/python3.8/site-packages/xarray/core/dataset.py", line 1644, in to_netcdf
    return to_netcdf(
  File "/g/data3/hh5/public/apps/miniconda3/envs/analysis3-20.10/lib/python3.8/site-packages/xarray/backends/api.py", line 1094, in to_netcdf
    store = store_open(target, mode, format, group, **kwargs)
  File "/g/data3/hh5/public/apps/miniconda3/envs/analysis3-20.10/lib/python3.8/site-packages/xarray/backends/netCDF4_.py", line 364, in open
    return cls(manager, group=group, mode=mode, lock=lock, autoclose=autoclose)
  File "/g/data3/hh5/public/apps/miniconda3/envs/analysis3-20.10/lib/python3.8/site-packages/xarray/backends/netCDF4_.py", line 314, in __init__
    self.format = self.ds.data_model
  File "/g/data3/hh5/public/apps/miniconda3/envs/analysis3-20.10/lib/python3.8/site-packages/xarray/backends/netCDF4_.py", line 373, in ds
    return self._acquire()
  File "/g/data3/hh5/public/apps/miniconda3/envs/analysis3-20.10/lib/python3.8/site-packages/xarray/backends/netCDF4_.py", line 367, in _acquire
    with self._manager.acquire_context(needs_lock) as root:
  File "/g/data3/hh5/public/apps/miniconda3/envs/analysis3-20.10/lib/python3.8/contextlib.py", line 113, in __enter__
    return next(self.gen)
  File "/g/data3/hh5/public/apps/miniconda3/envs/analysis3-20.10/lib/python3.8/site-packages/xarray/backends/file_manager.py", line 187, in acquire_context
    file, cached = self._acquire_with_cache_info(needs_lock)
  File "/g/data3/hh5/public/apps/miniconda3/envs/analysis3-20.10/lib/python3.8/site-packages/xarray/backends/file_manager.py", line 205, in _acquire_with_cache_info
    file = self._opener(*self._args, **kwargs)
  File "netCDF4/_netCDF4.pyx", line 2357, in netCDF4._netCDF4.Dataset.__init__
  File "netCDF4/_netCDF4.pyx", line 1925, in netCDF4._netCDF4._ensure_nc_success
PermissionError: [Errno 13] Permission denied: b'/g/data/w48/dm5220/data/exp_precip_change/ancil/tac_0.1.nc'
Traceback (most recent call last):
  File "/g/data/w48/dm5220/scripts/util/fix_polar_anom.py", line 9, in <module>
    from um_fileheaders import *
ModuleNotFoundError: No module named 'um_fileheaders'
